<?xml version="1.0"?>
<robot name="robot" xmlns:xacro="http://ros.org/wiki/xacro">
  <link name="base_link">
    <visual>
      <origin xyz="0 0 0.2" rpy="1.5707963 0 0"/>
      <geometry>
        <cylinder radius="0.05" length="0.1"/>
      </geometry>
    </visual>
    <collision>
      <origin xyz="0 0 0.2" rpy="1.5707963 0 0"/>
      <geometry>
        <cylinder radius="0.05" length="0.1"/>
      </geometry>
    </collision>
    <visual>
      <geometry>
        <box size="0.31 0.15 0.35"/>
      </geometry>
    </visual>
    <collision>
      <geometry>
        <box size="0.31 0.15 0.35"/>
      </geometry>
    </collision>
  </link>
  <joint name="joint_1_motor" type="revolute">
    <parent link="base_link"/>
    <child link="LINK_1"/>
    <axis xyz="0 1 0"/>
    <limit effort="10" lower="-6" upper="6" velocity="10"/>
    <origin xyz="0 0.075 0.3" rpy="0 0 0"/>
  </joint>
  <link name="LINK_1">
    <visual>
      <origin xyz="0 0 0" rpy="1.5707963 0 0"/>
      <geometry>
        <cylinder radius="0.0225" length="0.063"/>
      </geometry>
    </visual>
    <collision>
      <origin xyz="0 0 0" rpy="1.5707963 0 0"/>
      <geometry>
        <cylinder radius="0.0225" length="0.063"/>
      </geometry>
    </collision>
    <visual>
      <origin xyz="0 0.0315 0" rpy="1.5707963 0 0"/>
      <geometry>
        <sphere radius="0.0225"/>
      </geometry>
    </visual>
    <collision>
      <origin xyz="0 0.0315 0" rpy="1.5707963 0 0"/>
      <geometry>
        <sphere radius="0.0225"/>
      </geometry>
    </collision>
    <visual>
      <origin xyz="0 -0.0315 0" rpy="1.5707963 0 0"/>
      <geometry>
        <sphere radius="0.0225"/>
      </geometry>
    </visual>
    <collision>
      <origin xyz="0 -0.0315 0" rpy="1.5707963 0 0"/>
      <geometry>
        <sphere radius="0.0225"/>
      </geometry>
    </collision>
  </link>
  <joint name="joint_2_motor" type="revolute">
    <parent link="LINK_1"/>
    <child link="LINK_2"/>
    <axis xyz="1 0 0"/>
    <limit effort="10" lower="-6" upper="6" velocity="10"/>
    <origin xyz="0 0.04 0" rpy="0 0 0"/>
  </joint>
  <link name="LINK_2">
    <visual>
      <origin xyz="0 0.168 0" rpy="1.5707963 0 0"/>
      <geometry>
        <cylinder radius="0.0225" length="0.336"/>
      </geometry>
    </visual>
    <collision>
      <origin xyz="0 0.168 0" rpy="1.5707963 0 0"/>
      <geometry>
        <cylinder radius="0.0225" length="0.336"/>
      </geometry>
    </collision>
    <visual>
      <origin xyz="0 0.336 0" rpy="1.5707963 0 0"/>
      <geometry>
        <sphere radius="0.0225"/>
      </geometry>
    </visual>
    <collision>
      <origin xyz="0 0.336 0" rpy="1.5707963 0 0"/>
      <geometry>
        <sphere radius="0.0225"/>
      </geometry>
    </collision>
    <visual>
      <origin xyz="0 0 0" rpy="1.5707963 0 0"/>
      <geometry>
        <sphere radius="0.0225"/>
      </geometry>
    </visual>
    <collision>
      <origin xyz="0 0 0" rpy="1.5707963 0 0"/>
      <geometry>
        <sphere radius="0.0225"/>
      </geometry>
    </collision>
  </link>
  <joint name="joint_3_motor" type="revolute">
    <parent link="LINK_2"/>
    <child link="LINK_3"/>
    <axis xyz="1 0 0"/>
    <limit effort="10" lower="-6" upper="6" velocity="10"/>
    <origin xyz="0 0.324 0" rpy="0 0 0"/>
  </joint>
  <link name="LINK_3">
    <visual>
      <origin xyz="0 0.087 0" rpy="1.5707963 0 0"/>
      <geometry>
        <cylinder radius="0.0225" length="0.186"/>
      </geometry>
    </visual>
    <collision>
      <origin xyz="0 0.087 0" rpy="1.5707963 0 0"/>
      <geometry>
        <cylinder radius="0.0225" length="0.186"/>
      </geometry>
    </collision>
    <visual>
      <origin xyz="0 0.18 0" rpy="1.5707963 0 0"/>
      <geometry>
        <sphere radius="0.0225"/>
      </geometry>
    </visual>
    <collision>
      <origin xyz="0 0.18 0" rpy="1.5707963 0 0"/>
      <geometry>
        <sphere radius="0.0225"/>
      </geometry>
    </collision>
    <visual>
      <origin xyz="0 -0.006 0" rpy="1.5707963 0 0"/>
      <geometry>
        <sphere radius="0.0225"/>
      </geometry>
    </visual>
    <collision>
      <origin xyz="0 -0.006 0" rpy="1.5707963 0 0"/>
      <geometry>
        <sphere radius="0.0225"/>
      </geometry>
    </collision>
  </link>
  <joint name="joint_4_motor" type="revolute">
    <parent link="LINK_3"/>
    <child link="LINK_4"/>
    <axis xyz="1 0 0"/>
    <limit effort="10" lower="-6" upper="6" velocity="10"/>
    <origin xyz="0 0.174 0" rpy="0 0 0"/>
  </joint>
  <link name="LINK_4">
    <visual>
      <origin xyz="0 0.161 0" rpy="1.5707963 0 0"/>
      <geometry>
        <cylinder radius="0.0225" length="0.334"/>
      </geometry>
    </visual>
    <collision>
      <origin xyz="0 0.161 0" rpy="1.5707963 0 0"/>
      <geometry>
        <cylinder radius="0.0225" length="0.334"/>
      </geometry>
    </collision>
    <visual>
      <origin xyz="0 0.328 0" rpy="1.5707963 0 0"/>
      <geometry>
        <sphere radius="0.0225"/>
      </geometry>
    </visual>
    <collision>
      <origin xyz="0 0.328 0" rpy="1.5707963 0 0"/>
      <geometry>
        <sphere radius="0.0225"/>
      </geometry>
    </collision>
    <visual>
      <origin xyz="0 -0.006 0" rpy="1.5707963 0 0"/>
      <geometry>
        <sphere radius="0.0225"/>
      </geometry>
    </visual>
    <collision>
      <origin xyz="0 -0.006 0" rpy="1.5707963 0 0"/>
      <geometry>
        <sphere radius="0.0225"/>
      </geometry>
    </collision>
  </link>
  <joint name="joint_5_motor" type="revolute">
    <parent link="LINK_4"/>
    <child link="LINK_5"/>
    <axis xyz="0 1 0"/>
    <limit effort="10" lower="-6" upper="6" velocity="10"/>
    <origin xyz="0 0.324 0" rpy="0 0 0"/>
  </joint>
  <link name="LINK_5">
    <visual>
      <origin xyz="0 0.01 0" rpy="1.5707963 0 0"/>
      <geometry>
        <cylinder radius="0.0225" length="0.04"/>
      </geometry>
    </visual>
    <collision>
      <origin xyz="0 0.01 0" rpy="1.5707963 0 0"/>
      <geometry>
        <cylinder radius="0.0225" length="0.04"/>
      </geometry>
    </collision>
    <visual>
      <origin xyz="0 0.03 0" rpy="1.5707963 0 0"/>
      <geometry>
        <sphere radius="0.0225"/>
      </geometry>
    </visual>
    <collision>
      <origin xyz="0 0.03 0" rpy="1.5707963 0 0"/>
      <geometry>
        <sphere radius="0.0225"/>
      </geometry>
    </collision>
    <visual>
      <origin xyz="0 -0.01 0" rpy="1.5707963 0 0"/>
      <geometry>
        <sphere radius="0.0225"/>
      </geometry>
    </visual>
    <collision>
      <origin xyz="0 -0.01 0" rpy="1.5707963 0 0"/>
      <geometry>
        <sphere radius="0.0225"/>
      </geometry>
    </collision>
  </link>
  <joint name="joint_6_motor" type="revolute">
    <parent link="LINK_5"/>
    <child link="LINK_6"/>
    <axis xyz="1 0 0"/>
    <limit effort="10" lower="-6" upper="6" velocity="10"/>
    <origin xyz="0 0.03 0" rpy="0 0 0"/>
  </joint>
  <link name="LINK_6">
    <visual>
      <origin xyz="0 0.055 0" rpy="0 0 0"/>
      <geometry>
        <box size="0.25 0.02 0.06"/>
      </geometry>
    </visual>
    <collision>
      <origin xyz="0 0.055 0" rpy="0 0 0"/>
      <geometry>
        <box size="0.25 0.02 0.06"/>
      </geometry>
    </collision>
    <visual>
      <origin xyz="0 0.025 0" rpy="1.5707963 0 0"/>
      <geometry>
        <cylinder radius="0.0225" length="0.032"/>
      </geometry>
    </visual>
    <collision>
      <origin xyz="0 0.025 0" rpy="1.5707963 0 0"/>
      <geometry>
        <cylinder radius="0.0225" length="0.032"/>
      </geometry>
    </collision>
    <visual>
      <origin xyz="0 0.041 0" rpy="1.5707963 0 0"/>
      <geometry>
        <sphere radius="0.0225"/>
      </geometry>
    </visual>
    <collision>
      <origin xyz="0 0.041 0" rpy="1.5707963 0 0"/>
      <geometry>
        <sphere radius="0.0225"/>
      </geometry>
    </collision>
    <visual>
      <origin xyz="0 0.009 0" rpy="1.5707963 0 0"/>
      <geometry>
        <sphere radius="0.0225"/>
      </geometry>
    </visual>
    <collision>
      <origin xyz="0 0.009 0" rpy="1.5707963 0 0"/>
      <geometry>
        <sphere radius="0.0225"/>
      </geometry>
    </collision>
  </link>
  <link name="ds_left">
  </link>
  <joint name="base_link_ds_left_joint" type="fixed">
    <parent link="base_link"/>
    <child link="ds_left"/>
    <origin xyz="0.07 0.055 0.34" rpy="0 -1.0089953 0"/>
  </joint>
  <link name="ds_right">
  </link>
  <joint name="base_link_ds_right_joint" type="fixed">
    <parent link="base_link"/>
    <child link="ds_right"/>
    <origin xyz="-0.07 0 0.34" rpy="3.1415927 -1.0471973 3.1415927"/>
  </joint>
  <link name="camera">
  </link>
  <joint name="base_link_camera_joint" type="fixed">
    <parent link="base_link"/>
    <child link="camera"/>
    <origin xyz="-9.28752e-07 0 0.35" rpy="3.1415927 2.6535897e-06 3.1415927"/>
  </joint>
</robot>
